---
title: "JavaScript: あとから個別に await することで並列化しようとすると危ない"
emoji: "🪧"
type: "idea" # tech: 技術記事 / idea: アイデア
topics: ["javascript", "concurrent", "parallel"]
published: true
---

## TL;DR

- 並列化したいときは [`Promise.all(...)`](https://developer.mozilla.org/en-US/docs/Web/JavaScript/Reference/Global_Objects/Promise/all) を使います。
- 複数の Promise を取り扱うときは上記含めた、 [`.race(...)`](https://developer.mozilla.org/en-US/docs/Web/JavaScript/Reference/Global_Objects/Promise/race), [`.any(...)`](https://developer.mozilla.org/en-US/docs/Web/JavaScript/Reference/Global_Objects/Promise/race), [`.allSettled(...)`](https://developer.mozilla.org/en-US/docs/Web/JavaScript/Reference/Global_Objects/Promise/allSettled) の使用を検討します。

## 解説

以下は Deno と Node で動かして試せるようにしています。

```js
// 実際には API 叩いたりとか
const get = async (a, b) => new Promise(r => setTimeout(() => r(a + b), 100));
// 実際には例外が投げられうる処理
const err = async () => {throw new Error('err')};
// これでもいい
// const err = async () => new Promise((_, j) => setTimeout(() => j(new Error("err")), 0));

async function main () {
  const prom1 = get(1, 2);
  const prom2 = err();
  const prom3 = get(2, 3);

  await prom1;
  await prom2;
  await prom3;
}

try {
  await main();
} catch (e) {
  console.log('catch!', e);
}
```

これを実行すると、Node では `UnhandledPromiseRejectionWarning`, Deno では `Uncaught (in promise) Error:` となります。

これは `prom1` を `await` している間に `prom2` が例外を投げて _Rejected_ に移行し _Unhandled Error_ になりますが、その時点では `.catch` などされていないので Unhandled Error のままになります。

以下のように修正することで正しく handle できます。

```js
async function main () {
  const prom1 = get(1, 2);
  const prom2 = err();
  const prom3 = get(2, 3);

  await Promise.all([prom1, prom2, prom3]);
}
```

## 経緯

OSS でこの書き方を見かけることがありました。一見良さそうで直す能動的な理由がないために放置でいいかと思っていましたが、問題が発生しうることがわかり、今後簡単に参照できるように記事にしました。

この問題は https://zenn.dev/qnighy/articles/0aa6ec47248d80 でも触れられています。 `Promise` についてすべてを知りたい方は非常に面白いのでぜひ読んでみてください。
